Internal Server Error: /person/signup/
Traceback (most recent call last):
  File "/home/rwikdutta/anaconda3/envs/env_blood_donor/lib/python3.6/site-packages/django/core/handlers/exception.py", line 34, in inner
    response = get_response(request)
  File "/home/rwikdutta/anaconda3/envs/env_blood_donor/lib/python3.6/site-packages/django/core/handlers/base.py", line 126, in _get_response
    response = self.process_exception_by_middleware(e, request)
  File "/home/rwikdutta/anaconda3/envs/env_blood_donor/lib/python3.6/site-packages/django/core/handlers/base.py", line 124, in _get_response
    response = wrapped_callback(request, *callback_args, **callback_kwargs)
  File "/home/rwikdutta/anaconda3/envs/env_blood_donor/lib/python3.6/site-packages/django/views/decorators/csrf.py", line 54, in wrapped_view
    return view_func(*args, **kwargs)
  File "/home/rwikdutta/anaconda3/envs/env_blood_donor/lib/python3.6/site-packages/django/views/generic/base.py", line 68, in view
    return self.dispatch(request, *args, **kwargs)
  File "/home/rwikdutta/anaconda3/envs/env_blood_donor/lib/python3.6/site-packages/rest_framework/views.py", line 495, in dispatch
    response = self.handle_exception(exc)
  File "/home/rwikdutta/anaconda3/envs/env_blood_donor/lib/python3.6/site-packages/rest_framework/views.py", line 455, in handle_exception
    self.raise_uncaught_exception(exc)
  File "/home/rwikdutta/anaconda3/envs/env_blood_donor/lib/python3.6/site-packages/rest_framework/views.py", line 492, in dispatch
    response = handler(request, *args, **kwargs)
  File "/home/rwikdutta/PycharmProjects/blood_donor/person/views.py", line 15, in post
    a[0]
NameError: name 'a' is not defined
"POST /person/signup/ HTTP/1.1" 500 21202
"GET /person/own_info/ HTTP/1.1" 200 375
Internal Server Error: /person/signup/
Traceback (most recent call last):
  File "/home/rwikdutta/anaconda3/envs/env_blood_donor/lib/python3.6/site-packages/django/core/handlers/exception.py", line 34, in inner
    response = get_response(request)
  File "/home/rwikdutta/anaconda3/envs/env_blood_donor/lib/python3.6/site-packages/django/core/handlers/base.py", line 126, in _get_response
    response = self.process_exception_by_middleware(e, request)
  File "/home/rwikdutta/anaconda3/envs/env_blood_donor/lib/python3.6/site-packages/django/core/handlers/base.py", line 124, in _get_response
    response = wrapped_callback(request, *callback_args, **callback_kwargs)
  File "/home/rwikdutta/anaconda3/envs/env_blood_donor/lib/python3.6/site-packages/django/views/decorators/csrf.py", line 54, in wrapped_view
    return view_func(*args, **kwargs)
  File "/home/rwikdutta/anaconda3/envs/env_blood_donor/lib/python3.6/site-packages/django/views/generic/base.py", line 68, in view
    return self.dispatch(request, *args, **kwargs)
  File "/home/rwikdutta/anaconda3/envs/env_blood_donor/lib/python3.6/site-packages/rest_framework/views.py", line 495, in dispatch
    response = self.handle_exception(exc)
  File "/home/rwikdutta/anaconda3/envs/env_blood_donor/lib/python3.6/site-packages/rest_framework/views.py", line 455, in handle_exception
    self.raise_uncaught_exception(exc)
  File "/home/rwikdutta/anaconda3/envs/env_blood_donor/lib/python3.6/site-packages/rest_framework/views.py", line 492, in dispatch
    response = handler(request, *args, **kwargs)
  File "/home/rwikdutta/PycharmProjects/blood_donor/person/views.py", line 15, in post
    a[0]
NameError: name 'a' is not defined
"POST /person/signup/ HTTP/1.1" 500 20089
